Workbook

Sheet Included_102
A1: Ref. no. | B1: Citation key | C1: First author | D1: Title | E1: Year | F1: Venue | G1: Link | H1: Status | I1: Published version | J1: Preprint criterion | K1: Crit. a | L1: Crit. b | M1: Crit. c | N1: Model / Method | O1: Models used | P1: Models created | Q1: Model size | R1: Main tier | S1: Tiers covered (≤10B) | T1: Uses 7–10B | U1: Domain | V1: Training data | W1: Evaluation data | X1: Tasks | Y1: Key contribution | Z1: Country (first author)
A2: 5 | B2: belcak2025smalllanguagemodelsfuture | C2: Belcak et al. | D2: Small Language Models are the Future of Agentic AI | E2: 2025 | F2: arXiv preprint arXiv:2506.02153 | G2: https://arxiv.org/abs/2506.02153 | H2: Preprint | J2: b (405 citations) | L2: Yes | N2: Nemotron-H | O2: N/A | P2: N/A | Q2: N/A (position paper; discusses SLMs of ~1–9B, e.g. xLAM-2-8B) | R2: Mixed | S2: Moderate; Higher | T2: Yes | U2: Agentic AI Applications | V2: N/A | W2: N/A | X2: agentic AI applications | Y2: The paper argues that small language models are more suitable and economical for agentic AI applications compared to large language models. | Z2: United States
A3: 10 | B3: liu2024optimizing | C3: Liu et al. | D3: Optimizing RAG Techniques for Automotive Industry PDF Chatbots: A Case Study with Locally Deployed Ollama Models | E3: 2024 | F3: Proceedings of the 2024 3rd International Conference on Artificial Intelligence and Intelligent Information Processing | G3: https://arxiv.org/abs/2408.05933 | H3: Peer-reviewed | J3: Not applicable | O3: Llama models via Ollama; BGE embeddings and reranker (LangChain, LangGraph) | P3: Optimized local RAG pipeline and self-RAG agent | Q3: Not stated in abstract (locally deployed Ollama models) | R3: Not stated | S3: Not stated | T3: No | U3: Emerging & Cross-Cutting | V3: Proprietary automotive document corpus | W3: Automotive dataset, QReCC, CoQA | X3: Offline PDF question answering (RAG) for the automotive industry | Y3: Improves context precision/recall, answer relevancy and faithfulness over naive RAG, most on automotive documents | Z3: China
A4: 29 | B4: guo2023improving | C4: Guo et al. | D4: Improving Small Language Models on PubMedQA via Generative Data Augmentation | E4: 2023 | F4: arXiv preprint arXiv:2305.07804 | G4: https://arxiv.org/abs/2305.07804 | H4: Preprint | J4: b (43) | L4: Yes | N4: PubMedQA-SLM | O4: GPT-4 | P4: N/A | Q4: 1.6B | R4: Moderate | S4: Moderate | T4: No | U4: Healthcare & Biomedical | V4: PubMedQA | W4: PubMedQA | X4: medical question-answering | Y4: The paper introduces a novel method for improving small language models in the medical domain using LLM-based generative data augmentation. | Z4: United States
A5: 30 | B5: vishwanath2024medmobile | C5: Vishwanath et al. | D5: MedMobile: A Mobile-Sized Language Model with Clinical Capabilities | E5: 2024 | F5: arXiv preprint arXiv:2410.09019 | G5: https://doi.org/10.1136/bmjdhai-2025-000068 | H5: Peer-reviewed | I5: Published version: BMJ Digital Health & AI | J5: Not applicable | N5: MedMobile | O5: phi-3-mini | P5: MedMobile | Q5: 3.8B | R5: Moderate | S5: Moderate | T5: No | U5: Healthcare & Biomedical | V5: N/A | W5: MultiMedQA, Medbullets | X5: medical Q&A | Y5: Introduction of MedMobile, a 3.8 billion parameter language model optimized for mobile use in medical applications. | Z5: United States
A6: 32 | B6: zheng2026adaptive | C6: Zheng et al. | D6: Adaptive, Privacy-Preserving Small Language Models for Multi-Task Clinical Assistance | E6: 2026 | F6: Journal of Imaging Informatics in Medicine | G6: https://mdanderson.elsevierpure.com/en/publications/adaptive-privacy-preserving-small-language-models-for-multi-task-/ | H6: Peer-reviewed | J6: Not applicable | N6: Clinical-SLM | O6: GPT-4o, OPT-350m | P6: N/A | Q6: 350M | R6: Compact | S6: Compact | T6: No | U6: Healthcare & Biomedical | V6: Open-i Indiana University Chest X-ray Dataset, in-house brain MRI DICOM metadata dataset | W6: N/A | X6: medical report labeling, DICOM series description harmonization, impression generation | Y6: A multi-task SLM with LoRA fine-tuning outperforms GPT-4o on multiple clinical tasks while ensuring patient privacy. | Z6: United States
A7: 33 | B7: thalken2023law | C7: Thalken et al. | D7: Modeling Legal Reasoning: LM Annotation at the Edge of Human Agreement | E7: 2023 | F7: Proceedings of the 2023 Conference on Empirical Methods in Natural Language Processing | G7: https://aclanthology.org/2023.emnlp-main.575 | H7: Peer-reviewed | J7: Not applicable | N7: LEGAL-BERT | O7: LEGAL-BERT | P7: N/A | Q7: Legal-BERT (110M); Llama-2-Chat 7B as comparator | R7: Compact | S7: Compact | T7: No | U7: Law & Finance | V7: Annotated dataset of historical United States Supreme Court opinions | W7: N/A | X7: document classification, legal reasoning classification | Y7: The paper develops a new dataset of domain-expert annotations and demonstrates that fine-tuning models significantly improves performance on complex legal reasoning tasks. | Z7: United States
A8: 34 | B8: harsha2026synthesizing | C8: Harsha et al. | D8: Synthesizing Question Answering Data from Financial Documents: An End-to-End Multi-Agent Approach | E8: 2026 | F8: Proceedings of the 19th Conference of the European Chapter of the Association for Computational Linguistics (Volume 5: Industry Track) | G8: https://aclanthology.org/2026.eacl-industry.51 | H8: Peer-reviewed | J8: Not applicable | N8: Financial-QA | O8: phi-3-mini,smollm-1.7b,smollm-360m | P8: N/A | Q8: 360M, 1.7B (SmolLM2) | R8: Moderate | S8: Compact; Moderate | T8: No | U8: Law & Finance | V8: N/A | W8: N/A | X8: question answering, numerical reasoning | Y8: Development of a modular, scalable end-to-end agentic pipeline for generating QA pairs from financial documents. | Z8: India
A9: 36 | B9: aixcoder | C9: Jiang et al. | D9: aiXcoder-7B: A Lightweight and Effective Large Language Model for Code Processing | E9: 2025 | F9: 2025 IEEE/ACM 47th International Conference on Software Engineering: Software Engineering in Practice (ICSE-SEIP) | G9: https://arxiv.org/abs/2410.13187 | H9: Peer-reviewed | J9: Not applicable | N9: aiXcoder-7B | O9: N/A | P9: aiXcoder-7B | Q9: 7B | R9: Higher | S9: Higher | T9: Yes | U9: Coding & Software Eng. | V9: 1.2 trillion unique tokens | W9: five popular code completion benchmarks, a new benchmark collected by this paper | X9: code completion | Y9: The paper presents aiXcoder-7B, a lightweight LLM for code completion that achieves high accuracy with a smaller model size. | Z9: China
A10: 37 | B10: joshi2024flame | C10: Joshi et al. | D10: FLAME: A Small Language Model for Spreadsheet Formulas | E10: 2024 | F10: Proceedings of the AAAI Conference on Artificial Intelligence | G10: https://ojs.aaai.org/index.php/AAAI/article/view/29197 | H10: Peer-reviewed | J10: Not applicable | N10: FLAME | O10: T5-small | P10: FLAME | Q10: 60M | R10: Lightweight | S10: Lightweight | T10: No | U10: Coding & Software Eng. | V10: N/A | W10: N/A | X10: formula repair, formula completion, formula retrieval | Y10: FLAME is a transformer-based model trained exclusively on Excel formulas that achieves competitive performance while being substantially smaller than existing models. | Z10: United States
A11: 38 | B11: COTTON | C11: Yang et al. | D11: Chain-of-Thought in Neural Code Generation: From and For Lightweight Language Models | E11: 2024 | F11: IEEE Transactions on Software Engineering | G11: https://arxiv.org/abs/2312.05562 | H11: Peer-reviewed | J11: Not applicable | N11: COTTON | O11: GPT4, ChatGLM, Gemini, gpt-3.5-turbo | P11: COTTON | Q11: CodeT5+ 6B and other <10B ℓLMs | R11: Moderate | S11: Moderate | T11: No | U11: Coding & Software Eng. | V11: N/A | W11: N/A | X11: code generation | Y11: The study presents COTTON, a novel approach that leverages lightweight language models to automatically generate Chain of Thought for improved code generation. | Z11: China
A12: 39 | B12: duan2023perfrl | C12: Duan et al. | D12: PerfRL: A Small Language Model Framework for Efficient Code Optimization | E12: 2023 | F12: arXiv preprint arXiv:2312.05657 | G12: https://arxiv.org/abs/2312.05657 | H12: Preprint | J12: b (10) | L12: Yes | N12: PerfRL | O12: CodeT5 | P12: PerfRL | Q12: 60M (CodeT5) | R12: Lightweight | S12: Lightweight | T12: No | U12: Coding & Software Eng. | V12: PIE | W12: N/A | X12: code optimization | Y12: Introduction of PerfRL, a framework leveraging small language models and reinforcement learning for efficient code optimization. | Z12: United States
A13: 40 | B13: marton2026investigating | C13: Marton et al. | D13: Investigating the Refactoring Capabilities of Small Open-Weight Language Models | E13: 2026 | F13: Software | G13: https://doi.org/10.3390/software5020019 | H13: Peer-reviewed | J13: Not applicable | N13: SLM-Refactoring | O13: N/A | P13: N/A | Q13: 0.5B, 8B | R13: Higher | S13: Compact; Higher | T13: Yes | U13: Coding & Software Eng. | V13: N/A | W13: 3,453 Python programs | X13: refactoring | Y13: This paper analyzes the refactoring capabilities of small open-weight language models, focusing on behavior preservation and code quality improvement. | Z13: Hungary
A14: 41 | B14: MMhasan2026 | C14: Hasan et al. | D14: Assessing Small Language Models for Code Generation: An Empirical Study with Benchmarks | E14: 2026 | F14: Journal of Systems and Software | G14: https://arxiv.org/abs/2507.03160 | H14: Peer-reviewed | J14: Not applicable | N14: Code-Gen Study | O14: 20 open-source SLMs | P14: N/A | Q14: 0.4B to 10B | R14: Higher | S14: Compact; Moderate; Higher | T14: Yes | U14: Coding & Software Eng. | V14: N/A | W14: HumanEval, MBPP, Mercury, HumanEvalPack, CodeXGLUE | X14: code generation | Y14: This study presents a comprehensive empirical evaluation of 20 open-source SLMs on diverse code-related benchmarks. | Z14: Finland
A15: 42 | B15: wu2024datagpt | C15: Wu et al. | D15: DataGpt-SQL-7B: An Open-Source Language Model for Text-to-SQL | E15: 2024 | F15: arXiv preprint arXiv:2409.15985 | G15: https://arxiv.org/abs/2409.15985 | H15: Preprint | J15: b (12) | L15: Yes | N15: DataGpt-SQL-7B | O15: N/A | P15: DataGpt-sql | Q15: 7B | R15: Higher | S15: Higher | T15: Yes | U15: Coding & Software Eng. | V15: N/A | W15: spider-dev | X15: text-to-SQL | Y15: The paper presents DataGpt-sql, a fine-tuned model for translating natural language queries into SQL commands with high accuracy. | Z15: China
A16: 43 | B16: readerlmv2 | C16: Wang et al. | D16: Readerlm-v2: Small language model for HTML to markdown and JSON | E16: 2025 | F16: arXiv preprint arXiv:2503.01151 | G16: https://arxiv.org/abs/2503.01151 | H16: Preprint | J16: b (17); c (released model) | L16: Yes | M16: Yes | N16: ReaderLM-v2 | O16: Qwen2.5 | P16: ReaderLM-v2 | Q16: 1.5B | R16: Moderate | S16: Moderate | T16: No | U16: Coding & Software Eng. | V16: N/A | W16: N/A | X16: structured content extraction | Y16: Introduction of a novel three-stage data synthesis pipeline and a comprehensive training strategy for structured content extraction. | Z16: Germany
A17: 44 | B17: tinyrs | C17: Koksal et al. | D17: TinyRS-R1: Compact Vision Language Model for Remote Sensing | E17: 2025 | F17: IEEE Geoscience and Remote Sensing Letters | G17: https://doi.org/10.1109/LGRS.2025.3562290 | H17: Peer-reviewed | J17: Not applicable | N17: TinyRS | O17: Qwen2-VL | P17: TinyRS, TinyRS-R1 | Q17: 2B | R17: Moderate | S17: Moderate | T17: No | U17: Sustainability, Materials & Life Sci. | V17: million-scale satellite images, VHM visual instruction dataset | W17: N/A | X17: classification, VQA, grounding, open-ended QA | Y17: Introduction of TinyRS and TinyRS-R1, the first domain-specialized small VLMs for remote sensing with reasoning capabilities. | Z17: Turkey
A18: 45 | B18: alchembert | C18: Wang et al. | D18: Exploring Lightweight Language Models for Materials Informatics with AlchemBERT | E18: 2025 | F18: Cell Reports Physical Science | G18: https://doi.org/10.1016/j.xcrp.2025.102724 | H18: Peer-reviewed | J18: Not applicable | N18: AlchemBERT | O18: BERT-base | P18: AlchemBERT | Q18: 110M | R18: Compact | S18: Compact | T18: No | U18: Sustainability, Materials & Life Sci. | V18: Matbench | W18: N/A | X18: material property prediction | Y18: Demonstrates that language models effectively represent and predict material structures, outperforming traditional approaches. | Z18: China
A19: 46 | B19: pepbert | C19: Du et al. | D19: PepBERT: Lightweight Language Models for Bioactive Peptide Representation | E19: 2026 | F19: Future Foods | G19: https://doi.org/10.1016/j.fufo.2026.100561 | H19: Peer-reviewed | J19: Not applicable | N19: PepBERT | O19: ESM-2 | P19: PepBERT-large, PepBERT-small | Q19: 4.9M, 1.86M | R19: Lightweight | S19: Lightweight | T19: No | U19: Sustainability, Materials & Life Sci. | V19: four custom peptide datasets comprising between 1.97 and 19.2 million peptide sequences | W19: UniParc | X19: peptide prediction | Y19: PepBERT effectively captures the sequential dependencies and positional context within peptide sequences, generating expressive and generalizable peptide embeddings. | Z19: United States
A20: 48 | B20: adavits | C20: Song et al. | D20: AdaVITS: Tiny VITS for Low Computing Resource Speaker Adaptation | E20: 2022 | F20: 2022 13th International Symposium on Chinese Spoken Language Processing (ISCSLP) | G20: https://arxiv.org/abs/2206.00208 | H20: Peer-reviewed | J20: Not applicable | N20: AdaVITS | O20: VITS | P20: AdaVITS | Q20: 8.97M | R20: Lightweight | S20: Lightweight | T20: No | U20: Audio & Speech | V20: N/A | W20: N/A | X20: speaker adaptation | Y20: The paper proposes AdaVITS, a lightweight TTS model for speaker adaptation that reduces parameters and computational complexity. | Z20: China
A21: 50 | B21: TitaNetbyjia | C21: Jia et al. | D21: A Compact End-to-End Model with Local and Global Context for Spoken Language Identification | E21: 2022 | F21: arXiv preprint arXiv:2210.15781 | G21: https://doi.org/10.21437/Interspeech.2023-2310 | H21: Peer-reviewed | I21: Published version: Interspeech 2023 | J21: Not applicable | N21: TitaNet-LID | O21: ContextNet | P21: TitaNet-LID | Q21: 12M–21M | R21: Lightweight | S21: Lightweight | T21: No | U21: Audio & Speech | V21: V oxLingua107 | W21: FLEURS | X21: spoken language identification | Y21: Introduction of TitaNet-LID, a compact model for Spoken Language Identification that captures local and global context effectively. | Z21: United States
A22: 51 | B22: husni2023toxic | C22: Husni et al. | D22: Lightweight Toxicity Detection in Spoken Language: A Transformer-based Approach for Edge Devices | E22: 2023 | F22: arXiv preprint | G22: https://arxiv.org/abs/2304.11408 | H22: Preprint | J22: b (9) | L22: Yes | N22: Wav2Vec2-Toxicity | O22: wav2vec2.0 | P22: N/A | Q22: wav2vec 2.0 base, compressed to 25.9 MB | R22: Lightweight | S22: Lightweight | T22: No | U22: Audio & Speech | V22: DeToxy-B, public dataset | W22: N/A | X22: toxicity detection | Y22: The paper proposes a lightweight transformer model for toxicity detection in spoken language, optimized for edge devices. | Z22: Qatar
A23: 52 | B23: hatetinyllm | C23: Sen et al. | D23: HateTinyLLM : Hate Speech Detection Using Tiny Large Language Models | E23: 2024 | F23: arXiv preprint arXiv:2405.01577 | G23: https://arxiv.org/abs/2405.01577 | H23: Preprint | J23: b (12) | L23: Yes | N23: HateTinyLLM | O23: mixtral-7b, PY007/TinyLlama-1.1B-step-50K-105b, Microsoft/phi-2, facebook/opt-1.3b | P23: HateTinyLLM | Q23: 1.1B–7B (TinyLlama-1.1B, OPT-1.3B, Phi-2, Mistral-7B) | R23: Moderate | S23: Moderate; Higher | T23: Yes | U23: Audio & Speech | V23: N/A | W23: N/A | X23: hate speech detection | Y23: Introduction of HateTinyLLM, a novel framework for efficient hate speech detection using tiny large language models. | Z23: India
A24: 54 | B24: eureka | C24: Zhang et al. | D24: Eureka-Audio: Triggering Audio Intelligence in Compact Language Models | E24: 2026 | F24: arXiv preprint arXiv:2602.13954 | G24: https://arxiv.org/abs/2602.13954 | H24: Preprint | J24: a (code: github.com/Alittleegg/Eureka-Audio) | K24: Yes | N24: Eureka-Audio | O24: Qwen3-1.7B-base | P24: Eureka-Audio | Q24: 1.7B | R24: Moderate | S24: Moderate | T24: No | U24: Audio & Speech | V24: N/A | W24: MMAU benchmark, ASR, knowledge reasoning, safety, instruction following, paralinguistic benchmarks | X24: automatic speech recognition, audio understanding, dense audio captioning | Y24: Eureka-Audio achieves competitive performance in audio understanding with only 1.7B parameters, outperforming larger models. | Z24: China
A25: 55 | B25: deshmukh2026mellow | C25: Deshmukh et al. | D25: Mellow: A Small Audio Language Model for Reasoning | E25: 2026 | F25: Advances in Neural Information Processing Systems | G25: https://neurips.cc/virtual/2025/poster/115468 | H25: Peer-reviewed | J25: Not applicable | N25: Mellow | O25: Qwen2 Audio | P25: Mellow | Q25: 167M | R25: Compact | S25: Compact | T25: No | U25: Audio & Speech | V25: ReasonAQA, audio captioning datasets | W25: MMAU | X25: audio understanding, deductive reasoning, comparative reasoning | Y25: Introduction of Mellow, a small audio-language model designed for reasoning tasks, achieving state-of-the-art performance among small models. | Z25: United States
A26: 56 | B26: PRISM | C26: Ravichandran et al. | D26: Distilling On-Device Language Models for Robot Planning with Minimal Human Intervention | E26: 2025 | F26: arXiv preprint arXiv:2506.17486 | G26: https://openreview.net/forum?id=93bWCbhXJR | H26: Peer-reviewed | I26: Published version: CoRL 2025 | J26: Not applicable | N26: PRISM | O26: Llama-3.2-3B, GPT-4o | P26: PRISM | Q26: 3B (Llama-3.2-3B) | R26: Moderate | S26: Moderate | T26: No | U26: Robotics & Real-Time | V26: synthetic dataset | W26: N/A | X26: robot planning, mapping, exploration, manipulation, household assistance | Y26: Introduction of PRISM, a framework for distilling small language models for on-device robot planning. | Z26: United States
A27: 57 | B27: li2024transformer | C27: Li et al. | D27: Transformer-Lite: High-Efficiency Deployment of Large Language Models on Mobile Phone GPUs | E27: 2024 | F27: arXiv preprint arXiv:2403.20041 | G27: https://arxiv.org/abs/2403.20041 | H27: Preprint | J27: b (27) | L27: Yes | N27: Transformer-Lite | O27: ChatGLM2, Gemma | P27: Transformer-Lite | Q27: 2B, 6B, 14B | R27: Moderate | S27: Moderate | T27: No | U27: Robotics & Real-Time | V27: N/A | W27: N/A | X27: intelligent assistants, text summarization, translation, multi-modality | Y27: The paper proposes Transformer-Lite, an engine for high-efficiency deployment of LLMs on mobile GPUs, achieving significant speed improvements. | Z27: China
A28: 58 | B28: jang2025edge | C28: Jang et al. | D28: Edge-First Language Model Inference: Models, Metrics, and Tradeoffs | E28: 2025 | F28: 2025 IEEE 45th International Conference on Distributed Computing Systems Workshops (ICDCSW) | G28: https://arxiv.org/abs/2505.16508 | H28: Peer-reviewed | J28: Not applicable | N28: Edge-Cloud | O28: ChatGPT-4o | P28: N/A | Q28: 0.5B–3B on device (larger cloud comparators) | R28: Moderate | S28: Compact; Moderate | T28: No | U28: Robotics & Real-Time | V28: N/A | W28: MMLU, GSM8K, HumanEval | X28: language comprehension, answering complex queries, arithmetic reasoning, contextual understanding, sentiment analysis, text categorization, factual retrieval, code generation | Y28: This work examines the interplay between edge and cloud deployments for Small Language Models, providing insights into performance-cost tradeoffs. | Z28: United Kingdom
A29: 59 | B29: tian2026floe | C29: Tian et al. | D29: Floe: Federated Specialization for Real-Time LLM–SLM Inference | E29: 2026 | F29: IEEE Transactions on Parallel and Distributed Systems | G29: https://arxiv.org/abs/2602.14302 | H29: Peer-reviewed | J29: Not applicable | N29: Floe | O29: LLMs, SLMs | P29: Floe | Q29: Gemma-2B, Llama-7B on device (larger cloud models) | R29: Moderate | S29: Moderate; Higher | T29: Yes | U29: Robotics & Real-Time | V29: N/A | W29: N/A | X29: Federated learning, Privacy-Preserving, Edge-Cloud Collaboration | Y29: Floe enhances user privacy and personalization while improving model performance and reducing inference latency on edge devices. | Z29: China
A30: 60 | B30: tian2025clone | C30: Tian et al. | D30: CLONE: Customizing LLMs for Efficient Latency-Aware Inference at the Edge | E30: 2025 | F30: 2025 USENIX Annual Technical Conference (USENIX ATC 25) | G30: https://www.usenix.org/conference/atc25/presentation/tian | H30: Peer-reviewed | J30: Not applicable | N30: CLONE | O30: Llama-7B, GPT-3 | P30: CLONE | Q30: Gemma-2B, Llama-2-7B, Vicuna-7B | R30: Higher | S30: Moderate; Higher | T30: Yes | U30: Robotics & Real-Time | V30: N/A | W30: N/A | X30: inference optimization | Y30: The paper presents CLONE, an algorithm-hardware co-design for optimizing LLMs on edge devices to balance latency, energy consumption, and model accuracy. | Z30: China
A31: 61 | B31: swahbert | C31: Martin et al. | D31: SwahBERT: Language Model of Swahili | E31: 2022 | F31: Proceedings of the 2022 Conference of the North American Chapter of the Association for Computational Linguistics: Human Language Technologies | G31: https://aclanthology.org/2022.naacl-main.23 | H31: Peer-reviewed | J31: Not applicable | N31: SwahBERT | O31: multilingual BERT | P31: SwahBERT | Q31: ~105M (BERT-base) | R31: Compact | S31: Compact | T31: No | U31: Natural Language Processing | V31: pre-training dataset, emotion classification dataset | W31: N/A | X31: emotion classification | Y31: Introduction of SwahBERT, a new language model for Swahili, which outperforms multilingual BERT in various tasks. | Z31: South Korea
A32: 62 | B32: inkubalm | C32: Tonja et al. | D32: InkubaLM: A Small Language Model for Low-Resource African Languages | E32: 2024 | F32: arXiv preprint arXiv:2408.17024 | G32: https://arxiv.org/abs/2408.17024 | H32: Preprint | J32: a, c (weights: huggingface.co/lelapa) | K32: Yes | M32: Yes | N32: InkubaLM | O32: GPT-3, BERT | P32: InkubaLM | Q32: 0.4B | R32: Compact | S32: Compact | T32: No | U32: Natural Language Processing | V32: monolingual dataset for 5 African languages | W32: AfriMMLU, AfriXnli | X32: machine translation, question-answering, sentiment analysis, named entity recognition, parts of speech tagging, topic classification | Y32: Introduction of InkubaLM, the first open-source small multilingual language model for African languages. | Z32: South Africa
A33: 63 | B33: urdulm | C33: Ali et al. | D33: UrduLM: A Resource-Efficient Monolingual Urdu Language Model | E33: 2026 | F33: arXiv preprint arXiv:2601.17664 | G33: https://arxiv.org/abs/2601.17664 | H33: Preprint | J33: a (abstract: corpus, tokenizer and model weights released openly) | K33: Yes | N33: UrduLM | O33: LLaMA-2, GPT-4 | P33: UrduLM | Q33: 100M | R33: Compact | S33: Compact | T33: No | U33: Natural Language Processing | V33: 33GB Urdu corpus | W33: New benchmark datasets | X33: sentiment classification, grammar correction | Y33: Introduction of UrduLM, a competitive monolingual Urdu language model trained in low-resource settings. | Z33: Pakistan
A34: 64 | B34: albeto | C34: Canete et al. | D34: ALBETO and DistilBETO: Lightweight Spanish language models | E34: 2022 | F34: Proceedings of the thirteenth language resources and evaluation conference | G34: https://aclanthology.org/2022.lrec-1.457 | H34: Peer-reviewed | J34: Not applicable | N34: ALBETO-tiny | O34: ALBERT, DistilBERT, BETO | P34: ALBETO, DistilBETO | Q34: 5M, 67M, 223M | R34: Lightweight | S34: Lightweight; Compact | T34: No | U34: Natural Language Processing | V34: N/A | W34: GLUES, MLDoc, PAWS-X, XNLI, MLQA, SQAC, XQuAD | X34: natural language understanding, sentiment analysis, document classification, natural language inference | Y34: The paper presents ALBETO and DistilBETO, lightweight Spanish language models that achieve competitive results with fewer parameters. | Z34: Chile
A35: 65 | B35: lilmoo | C35: Fatimah et al. | D35: Raising Bars, Not Parameters: LilMoo Compact Language Model for Hindi | E35: 2026 | F35: arXiv preprint arXiv:2603.03508 | G35: https://arxiv.org/abs/2603.03508 | H35: Preprint | J35: a (models on huggingface.co/Polygl0t project page) | K35: Yes | N35: LilMoo | O35: N/A | P35: LilMoo | Q35: 0.6B | R35: Compact | S35: Compact | T35: No | U35: Natural Language Processing | V35: GigaLekh | W35: N/A | X35: N/A | Y35: Introduction of LilMoo, a Hindi language model trained from scratch to address linguistic inequalities in NLP. | Z35: Germany
A36: 66 | B36: bertabaporu | C36: Costa et al. | D36: BERTabaporu: Assessing a Genre-Specific Language Model for Portuguese NLP | E36: 2023 | F36: Proceedings of the 14th International Conference on Recent Advances in Natural Language Processing | G36: https://aclanthology.org/2023.ranlp-1.24 | H36: Peer-reviewed | J36: Not applicable | N36: BERTabaporu | O36: BERT, BERTimbau | P36: BERTabaporu | Q36: BERT-base (~110M) | R36: Compact | S36: Compact | T36: No | U36: Natural Language Processing | V36: 238 million tweets | W36: N/A | X36: stance prediction, mental health prediction, political alignment prediction | Y36: Introduction of BERTabaporu, a BERT model trained on a large Twitter corpus in Portuguese, and comparison with existing models. | Z36: Brazil
A37: 67 | B37: malbert | C37: Servan et al. | D37: mALBERT: Is a Compact Multilingual BERT Model Still Worth It? | E37: 2024 | F37: Proceedings of the 2024 joint international conference on computational linguistics, language resources and evaluation (LREC-COLING 2024) | G37: https://aclanthology.org/2024.lrec-main.960 | H37: Peer-reviewed | J37: Not applicable | N37: mALBERT | O37: BERT, ALBERT, GPT-4, LLaMA, BLOOM | P37: mALBERT | Q37: 12M (ALBERT) | R37: Lightweight | S37: Lightweight | T37: No | U37: Natural Language Processing | V37: Wikipedia | W37: GLUE, SQuAD | X37: Spoken Language Understanding, Question-Answering, Named Entity Recognition | Y37: The paper presents the release of a multilingual version of ALBERT, mALBERT, and studies the impact of subword tokenization on language performance. | Z37: France
A38: 68 | B38: hennara2025kuwain | C38: Hennara et al. | D38: Kuwain 1.5B: An Arabic SLM via Language Injection | E38: 2025 | F38: arXiv preprint arXiv:2504.15120 | G38: https://arxiv.org/abs/2504.15120 | H38: Preprint | J38: a (GitHub); b (5) | K38: Yes | L38: Yes | N38: Kuwain 1.5B | O38: TinyLlama 1.1B | P38: Kuwain 1.5B | Q38: 1.5B | R38: Moderate | S38: Moderate | T38: No | U38: Natural Language Processing | V38: N/A | W38: N/A | X38: Arabic language modelling | Y38: Injects Arabic into an English-centric small model without full retraining | Z38: Saudi Arabia
A39: 69 | B39: aldallal2025sadeed | C39: Aldallal et al. | D39: Sadeed: Advancing Arabic Diacritization Through Small Language Model | E39: 2025 | F39: arXiv preprint arXiv:2504.21635 | G39: https://arxiv.org/abs/2504.21635 | H39: Preprint | J39: b (7) | L39: Yes | N39: Sadeed | O39: Kuwain 1.5B | P39: Sadeed | Q39: ~1.5B (Kuwain-based) | R39: Moderate | S39: Moderate | T39: No | U39: Natural Language Processing | V39: Diacritized Arabic corpora | W39: SadeedDiac-25 | X39: Arabic diacritization | Y39: Fine-tuned SLM for Arabic diacritization plus SadeedDiac-25 benchmark | Z39: Saudi Arabia
A40: 70 | B40: gessler2022microbert | C40: Gessler and Zeldes | D40: MicroBERT: Effective Training of Low-resource Monolingual BERTs through Parameter Reduction and Multitask Learning | E40: 2022 | F40: MRL Workshop 2022 (ACL Anthology) | G40: https://doi.org/10.18653/v1/2022.mrl-1.9 | H40: Peer-reviewed | J40: Not applicable | N40: MicroBERT | O40: BERT, mBERT, RoBERTa, XLM-R, ELECTRA | P40: MicroBERT | Q40: <1% of mBERT (~<2M) | R40: Lightweight | S40: Lightweight | T40: No | U40: Natural Language Processing | V40: N/A | W40: NER, UD parsing | X40: MLM, POS tagging, parsing, NER | Y40: Small monolingual BERTs with multitask learning for low-resource languages | Z40: United States
...

Sheet Excluded_18
A1: Ref. no. | B1: Citation key | C1: First author | D1: Title | E1: Year | F1: Venue | G1: Link | H1: Reason (PRISMA category) | I1: Detail
A2: 31 | B2: hong2025nano | C2: Hong et al. | D2: Nano Bio-Agents (NBA): Small Language Model Agents for Genomics | E2: 2025 | F2: arXiv preprint arXiv:2509.19566 | G2: https://arxiv.org/abs/2509.19566 | H2: Preprint meeting none of the three criteria | I2: Preprint meeting none of the three criteria
A3: 35 | B3: nemo4paypal | C3: Garg et al. | D3: NEMO-4-PAYPAL: Leveraging NVIDIA's Nemo Framework for empowering PayPal's Commerce Agent | E3: 2026 | F3: arXiv preprint arXiv:2512.21578 | G3: https://arxiv.org/abs/2512.21578 | H3: Preprint meeting none of the three criteria | I3: Preprint meeting none of the three criteria
A4: 49 | B4: tinymlarduino | C4: V. et al. | D4: Implementation Of Tiny Machine Learning Models On Arduino 33 BLE For Gesture And Speech Recognition | E4: 2022 | F4: arXiv preprint arXiv:2207.12866 | G4: https://arxiv.org/abs/2207.12866 | H4: Not an SLM study | I4: Not a language model (CNN on a microcontroller)
A5: 85 | B5: pandey2026 | C5: Pandey et al. | D5: Can Small Language Models Use What They Retrieve? An Empirical Study of Retrieval Utilization Across Model Scale | E5: 2026 | F5: arXiv preprint arXiv:2603.11513 | G5: https://arxiv.org/abs/2603.11513 | H5: Preprint meeting none of the three criteria | I5: Preprint meeting none of the three criteria
A6: 94 | B6: neuberger | C6: Neuberger et al. | D6: Enabling Small Language Models for Text-to-Process Extraction: Balancing Accuracy and Efficiency through Distant Supervision | E6: 2026 | F6: arXiv preprint | G6: https://doi.org/10.1007/978-3-032-28117-3_9 | H6: Outside publication window | I6: Published after 30 April 2026 (CAiSE 2026, June 2026
A7: 95 | B7: yasuno | C7: Yasuno et al. | D7: Adapting Methods for Domain-Specific Japanese Small LMs: Scale, Architecture, and Quantization | E7: 2026 | F7: arXiv preprint arXiv:2603.18037 | G7: https://arxiv.org/abs/2603.18037 | H7: Preprint meeting none of the three criteria | I7: Preprint meeting none of the three criteria
A8: 96 | B8: plottwist | C8: Thorat et al. | D8: PlotTwist: A Creative Plot Generation Framework with Small Language Models | E8: 2026 | F8: arXiv preprint arXiv:2603.16410 | G8: https://arxiv.org/abs/2603.16410 | H8: Preprint meeting none of the three criteria | I8: Preprint meeting none of the three criteria
A9: 141 | B9: dogra2021analyzing | C9: Dogra et al. | D9: Analyzing DistilBERT for Sentiment Classification of Banking Financial News | E9: 2021 | F9: Intelligent Computing and Innovation on Data Science: Proceedings of ICTIDS 2021 | G9: https://doi.org/10.1007/978-981-16-3153-5_53 | H9: Outside publication window | I9: Published before 1 January 2022 (outside publication window)
A10: 146 | B10: wu2026tool | C10: Wu et al. | D10: Tool Calling is Linearly Readable and Steerable in Language Models | E10: 2026 | F10: arXiv preprint arXiv:2605.07990 | G10: https://arxiv.org/abs/2605.07990 | H10: Outside publication window | I10: Posted after the 30 Apr 2026 cutoff
A11: 150 | B11: banar2021generating | C11: Banar et al. | D11: Generating Music with Extreme Passages using GPT-2 | E11: 2021 | F11: Evo* 2021 | G11: https://arxiv.org/abs/2106.11804 | H11: Outside publication window | I11: Published before 1 January 2022 (outside publication window)
A12: 154 | B12: manik2025chatgpt | C12: Manik | D12: ChatGPT vs. DeepSeek: A Comparative Study on AI-Based Code Generation | E12: 2025 | F12: arXiv preprint arXiv:2502.18467 | G12: https://arxiv.org/abs/2502.18467 | H12: Not an SLM study | I12: No SLM studied (compares large LLMs)
A13: 155 | B13: abdalla2026deepseek | C13: Abdalla | D13: DeepSeek vs. ChatGPT: Which Performs Better in Python Coding? | E13: 2026 | F13: Journal of Information Technology Management | G13: https://jitm.ut.ac.ir/article_107165.html | H13: Not an SLM study | I13: No SLM studied (compares large LLMs)
... A19: 175 | B19: liang2024stacking | C19: Liang | D19: Stacking Small Language Models for Generalizability | E19: 2024 | F19: arXiv preprint arXiv:2410.15570 | G19: https://arxiv.org/abs/2410.15570 | H19: Preprint meeting none of the three criteria | I19: Preprint meeting none of the three criteria

Sheet PRISMA_Flow
A1: PRISMA 2020 flow diagram counts
A2: Blue cells are computed from the study sheets; others are records from the search and screening log.
A4: Stage | B4: Box | C4: n
A5: Identification | B5: Records identified: Google Scholar | C5: 481
A6: Identification | B6: Records identified: Semantic Scholar | C6: 465
A7: Identification | B7: Records identified: arXiv | C7: 210
A8: Identification | B8: Records identified: ACL Anthology | C8: 80
A9: Identification | B9: Records identified: ACM Digital Library | C9: 17
A10: Identification | B10: Records identified: IEEE Xplore | C10: 14
A11: Identification | B11: Records identified (total) | C11: =SUM(C5:C10)
A12: Identification | B12: Duplicates removed | C12: 172
A13: Identification | B13: Records removed for other reasons | C13: 40
A14: Screening | B14: Records screened | C14: =C11-C12-C13
A15: Screening | B15: Records excluded | C15: 920
A16: Screening | B16: Reports sought for retrieval | C16: =C14-C15
A17: Screening | B17: Reports not retrieved | C17: 15
A18: Eligibility | B18: Reports assessed for eligibility | C18: =C16-C17
A19: Eligibility | B19: Excluded: Not an SLM study | C19: =COUNTIF(Excluded_18!H2:H19,"Not an SLM study")
A20: Eligibility | B20: Excluded: Preprint meeting none of the three criteria | C20: =COUNTIF(Excluded_18!H2:H19,"Preprint*")
A21: Eligibility | B21: Excluded: Outside publication window | C21: =COUNTIF(Excluded_18!H2:H19,"Outside*")
A22: Eligibility | B22: Excluded: Venue not indexed | C22: =COUNTIF(Excluded_18!H2:H19,"Venue*")
A23: Eligibility | B23: Reports excluded (total) | C23: =SUM(C19:C22)
A24: Included | B24: Studies included in review | C24: =COUNTA(Included_102!A2:A103)
A25: Check | B25: Assessed − excluded = included | C25: =IF(C18-C23=C24,"✓ consistent","✗ mismatch")

Sheet Summary
A1: Summary of the 102 included studies
A2: Every count below is a live formula over Included_102; filter Included_102 to see the studies behind any number.
A4: Publication year (Figure 1)
A5: Category | B5: n | C5: %
A6: 2022 | B6: =COUNTIF(Included_102!$E$2:$E$103,2022) | C6: =B6/B$11
A7: 2023 | B7: =COUNTIF(Included_102!$E$2:$E$103,2023) | C7: =B7/B$11
A8: 2024 | B8: =COUNTIF(Included_102!$E$2:$E$103,2024) | C8: =B8/B$11
A9: 2025 | B9: =COUNTIF(Included_102!$E$2:$E$103,2025) | C9: =B9/B$11
A10: 2026 | B10: =COUNTIF(Included_102!$E$2:$E$103,2026) | C10: =B10/B$11
A11: Total | B11: =SUM(B6:B10) | C11: =B11/B11
A14: Main scale tier
A15: Category | B15: n | C15: %
A16: Lightweight | B16: =COUNTIF(Included_102!$R$2:$R$103,"Lightweight") | C16: =B16/B$22
A17: Compact | B17: =COUNTIF(Included_102!$R$2:$R$103,"Compact") | C17: =B17/B$22
A18: Moderate | B18: =COUNTIF(Included_102!$R$2:$R$103,"Moderate") | C18: =B18/B$22
A19: Higher | B19: =COUNTIF(Included_102!$R$2:$R$103,"Higher") | C19: =B19/B$22
A20: Mixed | B20: =COUNTIF(Included_102!$R$2:$R$103,"Mixed") | C20: =B20/B$22
A21: Not stated | B21: =COUNTIF(Included_102!$R$2:$R$103,"Not stated") | C21: =B21/B$22
A22: Total | B22: =SUM(B16:B21) | C22: =B22/B22
A25: Application domain (Figure 4, Tables 4–5)
A26: Category | B26: n | C26: %
A27: Natural Language Processing | B27: =COUNTIF(Included_102!$U$2:$U$103,"Natural Language Processing") | C27: =B27/B$37
A28: Agentic AI Applications | B28: =COUNTIF(Included_102!$U$2:$U$103,"Agentic AI Applications") | C28: =B28/B$37
A29: Coding & Software Eng. | B29: =COUNTIF(Included_102!$U$2:$U$103,"Coding & Software Eng.") | C29: =B29/B$37
A30: Healthcare & Biomedical | B30: =COUNTIF(Included_102!$U$2:$U$103,"Healthcare & Biomedical") | C30: =B30/B$37
A31: Robotics & Real-Time | B31: =COUNTIF(Included_102!$U$2:$U$103,"Robotics & Real-Time") | C31: =B31/B$37
A32: Audio & Speech | B32: =COUNTIF(Included_102!$U$2:$U$103,"Audio & Speech") | C32: =B32/B$37
A33: Emerging & Cross-Cutting | B33: =COUNTIF(Included_102!$U$2:$U$103,"Emerging & Cross-Cutting") | C33: =B33/B$37
A34: Sustainability, Materials & Life Sci. | B34: =COUNTIF(Included_102!$U$2:$U$103,"Sustainability, Materials & Life Sci.") | C34: =B34/B$37
A35: Law & Finance | B35: =COUNTIF(Included_102!$U$2:$U$103,"Law & Finance") | C35: =B35/B$37
A36: General (techniques / evaluation) | B36: =COUNTIF(Included_102!$U$2:$U$103,"General (techniques / evaluation)") | C36: =B36/B$37
A37: Total | B37: =SUM(B27:B36) | C37: =B37/B37
A38: Domain-specific (Figure 4) | B38: =COUNTIF(Included_102!$U$2:$U$103,"<>General (techniques / evaluation)")
A42: Publication status
A43: Category | B43: n | C43: %
A44: Peer-reviewed | B44: =COUNTIF(Included_102!$H$2:$H$103,"Peer-reviewed") | C44: =B44/B$46
A45: Preprint | B45: =COUNTIF(Included_102!$H$2:$H$103,"Preprint") | C45: =B45/B$46
A46: Total | B46: =SUM(B44:B45) | C46: =B46/B46
A49: Preprint inclusion criteria (a study may meet more than one)
A50: Criterion | B50: n
...
